Workbook

Sheet Dashboard
A1: 📊 Sales Pipeline Dashboard
B6: 🎯 KEY PERFORMANCE METRICS
B8: 📊 TOTAL PROJECTS | D8: 🟢 IN HAND | F8: 🟡 TENDER | H8: 💰 PIPELINE VALUE
B9: =D9+F9 -> 22 | D9: =COUNTIF('Projects Follow UP'!G:G,"in hand") -> 16 | F9: =COUNTIF('Projects Follow UP'!G:G,"Tender") -> 6 | H9: =SUM('Projects Follow UP'!O:O) -> 73877915
B10: Active Pipeline | D10: Confirmed Deals | F10: Pending Bids | H10: Total Estimated
C12: 📊 | D12: =SUMIF('Projects Follow UP'!G:G,"In Hand",'Projects Follow UP'!O:O) -> 18947100 | E12: 📋 | F12: =SUMIF('Projects Follow UP'!G:G,"Tender",'Projects Follow UP'!O:O) -> 54930815
B13: 🔥 HOT LEADS (7 DAYS) | D13: ✅ WON DEALS | F13: ❌ LOST DEALS | H13: ⚡ DUE TODAY
B14: =COUNTIFS('Hot Leads'!H:H,">="&(TODAY()-7),'Hot Leads'!H:H,"<="&TODAY()) -> 0 | D14: =COUNTIF('Projects Follow UP'!I:I,"Won") -> 0 | E14: = | F14: =COUNTIF('Projects Follow UP'!I:I,"Lost") -> 1 | H14: =COUNTIF('Hot Leads'!K:K,"<="&TODAY())+COUNTIF('Projects Follow UP'!N:N,"<="&TODAY()) -> 10
B15: New Contacts | D15: Closed Successfully | E15: =SUM('Won Deals'!G2:G176) -> 15962 | F15: Not Converted | H15: Actions Required
B17: 📈 HIT RATE | C17: =IFERROR(D14/(D14+F14),0) -> 0
B18: 📈 ANALYTICS & INSIGHTS
B20: 📊 Pipeline by Stage | D20: 📍 Projects by Location | F20: 📋 Projects by Status
B21: Stage | C21: Count | D21: Location | E21: Count | F21: Status | G21: Count
B22: In Hand | C22: =COUNTIF('Projects Follow UP'!G:G,"In Hand") -> 16 | D22: Jeddah | E22: =COUNTIF('Projects Follow UP'!H:H,"Jeddah") -> 10 | F22: RFQ Processing | G22: =COUNTIF('Projects Follow UP'!I:I,"*RFQ*") -> 5
B23: Tender | C23: =COUNTIF('Projects Follow UP'!G:G,"Tender") -> 6 | D23: Makkah | E23: =COUNTIF('Projects Follow UP'!H:H,"Makkah") -> 6 | F23: Negotiation | G23: =COUNTIF('Projects Follow UP'!I:I,"Negotiation") -> 1
B24: Won | C24: =COUNTIF('Projects Follow UP'!G:G,"Won") -> 0 | D24: Madinah | E24: =COUNTIF('Projects Follow UP'!H:H,"Madinah")+COUNTIF('Projects Follow UP'!H:H,"Madena") -> 0 | F24: Gather Info | G24: =COUNTIF('Projects Follow UP'!I:I,"*Gather*") -> 2
B25: Lost | C25: =COUNTIF('Projects Follow UP'!G:G,"Lost") -> 0 | D25: Riyadh | E25: =COUNTIF('Projects Follow UP'!H:H,"Riyadh") -> 4 | F25: Send to Client | G25: =COUNTIF('Projects Follow UP'!I:I,"*Send*") -> 11
D26: Khobar | E26: =COUNTIF('Projects Follow UP'!H:H,"Khobar")+COUNTIF('Projects Follow UP'!H:H,"Dammam") -> 1 | F26: Closed | G26: =COUNTIF('Projects Follow UP'!I:I,"*Closed*") -> 0
D27: Other | E27: =B9-SUM(E22:E26) -> 1
B40: 🎯 ACTION CENTER - Tasks Requiring Immediate Attention
B42: 🔥 HOT LEADS - Follow Up Required | I42: ⚡ QUICK UPDATE - Edit Action / Date
B43: Name | C43: Company | D43: Phone | E43: Position | F43: Action Required | G43: Action Date | H43: Days | I43: Client | J43: New Action Required | K43: New Action Date | L43: Status
B44: {=_xlfn.LET(_xlpm.data,_xlfn._xlws.FILTER(_xlfn.HSTACK(Hot_Leads[Name],Hot_Leads[Company],IF(Hot_Leads[Phone]<>"",TEXT(Hot_Leads[Phone],"0"),""),Hot_Leads[Position],Hot_Leads[Current Action Required],Hot_Leads[Current Action Date],TODAY()-Hot_Leads[Current Action Date]),(Hot_Leads[Current Action Date]>0)*(Hot_Leads[Current Action Date]<TODAY())*(Hot_Leads[Name]<>"")),IFERROR(_xlfn.TAKE(_xlfn._xlws.SORT(_xlpm.data,7,-1),15),"✓ No Hot Leads Due Today"))} -> ✓ No Hot Leads Due Today | I44: Mohamed Elkholy | J44: مفيش اخبار جديدة عنه | K44: 46243 | L44: =IF(AND(J44<>"",K44<>""),"✓ Synced","Add update") -> ✓ Synced | M44: 966541016847
I45: Mohamed Taqash | J45: Follow Up Next Week | K45: 46140 | L45: =IF(AND(J45<>"",K45<>""),"✓ Synced","Add update") -> ✓ Synced | M45: 966569972444
I46: Majdi I. Al-Zoubi | J46: ده خلاص مبقاش معايا مهندس عبدالرحمن قالي ان فيه حد مكمل معاه | K46: 46456 | L46: =IF(AND(J46<>"",K46<>""),"✓ Synced","Add update") -> ✓ Synced | M46: 966569548850
I47: Ashraf Gadallah | J47: في اجازة في مصر و هرجع يبعتلنا مشروع ديار الحرم عشان نخشه سوا | K47: 46265 | L47: =IF(AND(J47<>"",K47<>""),"✓ Synced","Add update") -> ✓ Synced | M47: 966562292293
I48: Yasser Bahussin | J48: قالي ان البرنامج هيرسى علينا و مستني بس موفقه الادارة | K48: 46250 | L48: =IF(AND(J48<>"",K48<>""),"✓ Synced","Add update") -> ✓ Synced | M48: 966506694282
I49: Sameh Saber | J49: Send Pre and follow up | K49: 46145 | L49: =IF(AND(J49<>"",K49<>""),"✓ Synced","Add update") -> ✓ Synced | M49: 966568061671
I50: Youssef Adwi | J50: عاوز رقم حد من المشتريات | K50: 46145 | L50: =IF(AND(J50<>"",K50<>""),"✓ Synced","Add update") -> ✓ Synced | M50: 966554711520
I51: Omar Alsaad | J51: هكلمه بكره تاني عشان اعرف التفاصيل الي قالي عليها | K51: 46145 | L51: =IF(AND(J51<>"",K51<>""),"✓ Synced","Add update") -> ✓ Synced | M51: 966549733284
I52: Ibrahim Ahmed | J52: هكلمه يوم الاتنين عشان اعرف التفاصيل الجديدة | K52: 46146 | L52: =IF(AND(J52<>"",K52<>""),"✓ Synced","Add update") -> ✓ Synced | M52: 966546468592
I53: Mohamed 3essa | J53: كلمته الاحد بس مردش عليا | K53: 46146 | L53: =IF(AND(J53<>"",K53<>""),"✓ Synced","Add update") -> ✓ Synced | M53: 966598803998
I54: Ibrahim Sabry | J54: مفيش جديد مش معاه مشاريع تانيه حاليا | K54: 46364 | L54: =IF(AND(J54<>"",K54<>""),"✓ Synced","Add update") -> ✓ Synced | M54: 201111448448
I55: Azazuddin Mohamed | J55: حدد معاه ميتنج يوم الثلاثاء 6/5/2026 | K55: 46148 | L55: =IF(AND(J55<>"",K55<>""),"✓ Synced","Add update") -> ✓ Synced | M55: 966505520073
I56: Mohamed Atef | J56: 0 | K56: 46149 | L56: =IF(AND(J56<>"",K56<>""),"✓ Synced","Add update") -> ✓ Synced | M56: 966544411842
I57: Ahmed Naserallah | J57: هتابع معاه الاسبوع الجي | K57: 46149 | L57: =IF(AND(J57<>"",K57<>""),"✓ Synced","Add update") -> ✓ Synced | M57: 966561333021
I58: Abo Sultan | J58: خد منه رقم حد من المهندسين او لوكيشن الشركة | K58: 46149 | L58: =IF(AND(J58<>"",K58<>""),"✓ Synced","Add update") -> ✓ Synced | M58: 966557077244
B59: 📋 PROJECTS - Follow Up Required | I59: ⚡ PROJECT QUICK UPDATE - Follow Up / Date
B60: Project # | C60: Opportunity | D60: Client | E60: Stage | F60: Action Required | G60: Action Date | H60: Days | I60: Project | J60: New Follow Up | K60: New Follow Up Date | L60: Status
B61: {=_xlfn.LET(_xlpm.data,_xlfn._xlws.FILTER(_xlfn.HSTACK('Projects Follow UP'!A5:A139,'Projects Follow UP'!B5:B139,'Projects Follow UP'!C5:C139,'Projects Follow UP'!G5:G139,'Projects Follow UP'!R5:R139,'Projects Follow UP'!S5:S139,TODAY()-'Projects Follow UP'!S5:S139),('Projects Follow UP'!S5:S139>0)*('Projects Follow UP'!S5:S139<TODAY())*('Projects Follow UP'!A5:A139<>"")),IFERROR(_xlfn.TAKE(_xlfn._xlws.SORT(_xlpm.data,7,-1),12),"✓ No Projects Due Today"))} -> ✓ No Projects Due Today | I61: PR1018 | J61: المشروع هيخلص اقصى حاجة يوم السبت و المشروع ده مهم جدا لابعد حد عشان نقدر ناخد الباكدج كاملة | K61: 46389 | L61: =IF(AND(J61<>"",K61<>""),"✓ Synced","Add update") -> ✓ Synced | M61: PR1018
...

Sheet Search
B2: 🔍 Search Engine
B4: 📅 SELECT PERIOD
B5: 📆 Date | C5: 📅 Week # | D5: 🗓️ Month | E5: 📊 Quarter
B6: 46144 | C6: =WEEKNUM(B6) -> 18 | D6: =MONTH(B6) -> 5 | E6: =ROUNDUP(MONTH(B6)/3,0) -> 2
B8: 📊 KPI DASHBOARD
B9: 🚗 F2F Visits (Daily) | C9: 📞 Calls (Daily) | D9: 🏢 New Accounts (Weekly) | E9: 💰 Quote Value (Weekly)
B10: =COUNTIFS('Master Report'!A:A,B6,'Master Report'!F:F,"F2F Meeting") -> 0 | C10: =COUNTIFS('Master Report'!A:A,B6,'Master Report'!F:F,"Call") -> 11 | D10: =COUNTIFS('Hot Leads'!H:H,">="&(B6-WEEKDAY(B6,2)+1),'Hot Leads'!H:H,"<="&B6) -> 26 | E10: =SUMIFS('Projects Follow UP'!O:O,'Projects Follow UP'!L:L,">="&(B6-WEEKDAY(B6,2)+1),'Projects Follow UP'!L:L,"<="&B6) -> 0
B11: Target: 3 | C11: Target: 12 | D11: Target: 5 | E11: Target: 2M SAR
B13: 📋 Tech Submittals (Monthly) | C13: 🔍 In-Hand Review (Monthly) | D13: 📝 Tender Review (Monthly) | E13: 🏆 Total Projects (Quarter)
B14: =COUNTIFS('Projects Follow UP'!L:L,">="&DATE(YEAR(B6),MONTH(B6),1),'Projects Follow UP'!L:L,"<="&EOMONTH(B6,0),'Projects Follow UP'!I:I,"*technical*") -> 0 | C14: =COUNTIFS('Projects Follow UP'!G:G,"In Hand") -> 16 | D14: =COUNTIFS('Projects Follow UP'!G:G,"Tender") -> 6 | E14: =COUNTIF('Projects Follow UP'!A5:A139,"<>") -> 135
B15: Target: 4 | C15: Target: 4 | D15: Target: 2 | E15: Pipeline Total
B17: 🔍 SEARCH ENGINE
B18: 🔎 Name / Company | C18: 📞 Phone Number | D18: 🏗️ Project Name | E18: 📍 Location
B19: sameh saber
B20: Search in: | C20: All
B22: 📋 Contact / Account RESULTS
B23: Name | C23: Company | D23: Phone | E23: Position / Status
B24: {=IFERROR( IF(B19<>"", _xlfn._xlws.FILTER(_xlfn.HSTACK('Hot Leads'!A:A,'Hot Leads'!C:C,'Hot Leads'!B:B,'Hot Leads'!G:G), (ISNUMBER(SEARCH(B19,'Hot Leads'!A:A))+ISNUMBER(SEARCH(B19,'Hot Leads'!C:C))) *('Hot Leads'!A:A<>"Name")*('Hot Leads'!A:A<>"")), IF(C19<>"", _xlfn._xlws.FILTER(_xlfn.HSTACK('Hot Leads'!A:A,'Hot Leads'!C:C,'Hot Leads'!B:B,'Hot Leads'!G:G), (ISNUMBER(SEARCH(C19,'Hot Leads'!B:B))) *('Hot Leads'!A:A<>"Name")*('Hot Leads'!A:A<>"")), IF(E19<>"", _xlfn._xlws.FILTER(_xlfn.HSTACK('Hot Leads'!A:A,'Hot Leads'!C:C,'Hot Leads'!B:B,'Hot Leads'!G:G), (ISNUMBER(SEARCH(E19,'Hot Leads'!E:E))) *('Hot Leads'!A:A<>"Name")*('Hot Leads'!A:A<>"")), "Enter search term above..."))), "No results found")} -> No results found
B36: 🏗️ PROJECT SEARCH
B37: Project # | C37: Opportunity | D37: Client Name | E37: Stage / Status
B38: {=IFERROR( IF(D19<>"", _xlfn._xlws.FILTER(_xlfn.HSTACK('Projects Follow UP'!A5:A139,'Projects Follow UP'!B5:B139,'Projects Follow UP'!C5:C139,'Projects Follow UP'!G5:G139), (ISNUMBER(SEARCH(D19,'Projects Follow UP'!B5:B139))+ISNUMBER(SEARCH(D19,'Projects Follow UP'!C5:C139))) *('Projects Follow UP'!A5:A139<>"")), IF(B19<>"", _xlfn._xlws.FILTER(_xlfn.HSTACK('Projects Follow UP'!A5:A139,'Projects Follow UP'!B5:B139,'Projects Follow UP'!C5:C139,'Projects Follow UP'!G5:G139), (ISNUMBER(SEARCH(B19,'Projects Follow UP'!C5:C139))+ISNUMBER(SEARCH(B19,'Projects Follow UP'!E5:E139))) *('Projects Follow UP'!A5:A139<>"")), IF(E19<>"", _xlfn._xlws.FILTER(_xlfn.HSTACK('Projects Follow UP'!A5:A139,'Projects Follow UP'!B5:B139,'Projects Follow UP'!C5:C139,'Projects Follow UP'!G5:G139), (ISNUMBER(SEARCH(E19,'Projects Follow UP'!H5:H139))) *('Projects Follow UP'!A5:A139<>"")), "Enter search term above..."))), "No projects found")} -> No projects found
B50: 📊 QUICK STATS & DATE RANGE
B51: ="Total: "&COUNTIF('Projects Follow UP'!A5:A139,"<>")&" Projects" -> Total: 135 Projects | C51: ="Hot Leads: "&COUNTIF('Hot Leads'!A2:A155,"<>") -> Hot Leads: 150 | D51: ="Pipeline: "&TEXT(SUM('Projects Follow UP'!O:O),"#,##0")&" SAR" -> Pipeline: 73,877,915 SAR | E51: ="Due Today: "&COUNTIFS('Hot Leads'!K:K,"<="&TODAY(),'Hot Leads'!K:K,"<>") -> Due Today: 0
B53: TECHNICAL SUBMITTALS TRACKER & SEARCH
B55: SEARCH BY PERIOD
B56: Week # | C56: Month | D56: Quarter | E56: Year
B57: 17 | C57: 4 | D57: 2 | E57: 2026
B59: SUBMITTALS COUNT RESULTS
B60: By Week | C60: By Month | D60: By Quarter | E60: By Year
B61: {=SUMPRODUCT((('Projects Follow UP'!$I$5:$I$139="Technical Submission")+('Projects Follow UP'!$I$5:$I$139="Technically Approved"))*(_xlfn.ISOWEEKNUM('Projects Follow UP'!$L$5:$L$139)=B57)*(YEAR('Projects Follow UP'!$L$5:$L$139)=E57))} -> 0 | C61: {=SUMPRODUCT((('Projects Follow UP'!$I$5:$I$139="Technical Submission")+('Projects Follow UP'!$I$5:$I$139="Technically Approved"))*(MONTH('Projects Follow UP'!$L$5:$L$139)=C57)*(YEAR('Projects Follow UP'!$L$5:$L$139)=E57))} -> 0 | D61: {=SUMPRODUCT((('Projects Follow UP'!$I$5:$I$139="Technical Submission")+('Projects Follow UP'!$I$5:$I$139="Technically Approved"))*(INT((MONTH('Projects Follow UP'!$L$5:$L$139)-1)/3)+1=D57)*(YEAR('Projects Follow UP'!$L$5:$L$139)=E57))} -> 0 | E61: {=SUMPRODUCT((('Projects Follow UP'!$I$5:$I$139="Technical Submission")+('Projects Follow UP'!$I$5:$I$139="Technically Approved"))*(YEAR('Projects Follow UP'!$L$5:$L$139)=E57))} -> 0
B63: OVERALL SUBMITTALS STATUS
B64: Tech Submission | C64: Tech Approved | D64: Total All Time | E64: Monthly Target
B65: =COUNTIF('Projects Follow UP'!$I:$I,"*Technical Submission*") -> 0 | C65: =COUNTIF('Projects Follow UP'!$I:$I,"*Technically Approved*") -> 0 | D65: =B65+C65 -> 0 | E65: 4
B67: Status: | C67: =IF(C61>=E65,"Target Met! ("&C61&"/"&E65&")","Need "&(E65-C61)&" more this month") -> Need 4 more this month
B69: TIP: Update Status in 'Projects Follow UP' (Col I) to 'Technical Submission' or 'Technically Approved' to track
B70: Current Status Values: Lost, Send to Client, RFQ Processing, Gather Information, Hold

Sheet Projects Follow UP
D1: No. In Hand Projects | E1: =COUNTIF(G5:G139, "In Hand") -> 16 | F1: Total Projects = | G1: =E1+E2 -> 22 | H1: Hit Rate % | I1: =COUNTIF(I5:I139, "Won") / COUNTA(I5:I139) -> 0 | J1: Total Amount | K1: =SUM(J5:J139) -> 73877915
D2: No. Tender Projects | E2: =COUNTIF(G5:G139, "Tender") -> 6
D3: Quality= | E3: =IF(COUNTIF(G5:G139,"In Hand")/(COUNTIF(G5:G139,"In Hand")+COUNTIF(G5:G139,"Tender"))>=0.7, "Excellent Quality ✅", IF(COUNTIF(G5:G139,"In Hand")/(COUNTIF(G5:G139,"In Hand")+COUNTIF(G5:G139,"Tender"))>=0.5, "Stable ⚖️", "Below Target ⚠️")) -> Excellent Quality ✅
A4: #PR | B4: Opportunity | C4: Client Name | D4: Client Phone Number | E4: Company Name | F4: Client Email | G4: Project Stage | H4: Project Location | I4: Status | J4: Est. value | K4: Action Done | L4: Action Date | M4: Follow Up | N4: Follow Up Date | O4: Est. value (SAR) | P4: Gone To Referral ? | Q4: Column1 | R4: Current Follow Up | S4: Current Follow Up Date
A5: PR1004 | B5: KIX Futsal Complex | C5: Mohamed Hanifa | D5: 966540654038 | E5: MHM | F5: hanifa@almagamsi.com | G5: Tender | H5: Jeddah | I5: Send to Client | J5: 337489 | K5: بعت للعميل التسعير و مستني الرد | L5: 46126 | M5: رقمه مغلق حاليا و بعتله واتساب | O5: =IFERROR(VALUE(SUBSTITUTE(TRIM(SUBSTITUTE(Projects_Follow_UP[[#This Row],[Est. value]],"SAR","")),",","")),0) -> 337489 | R5: {=_xlfn.LET(_xlpm.x,_xlfn.XLOOKUP(A5,Dashboard!$M$61:$M$72,Dashboard!$J$61:$J$72,""),IF(_xlpm.x<>"",_xlpm.x,M5))} -> رقمه مغلق حاليا و بعتله واتساب | S5: {=_xlfn.LET(_xlpm.x,_xlfn.XLOOKUP(A5,Dashboard!$M$61:$M$72,Dashboard!$K$61:$K$72,""),_xlpm.orig,N5,IF(_xlpm.x<>"",_xlpm.x,IF(OR(_xlpm.orig="",_xlpm.orig=0),"",_xlpm.orig)))}
A6: PR1007 | B6: International Medical Center IMC Obhur Hospital Project | C6: Omar Abdallah - Mazen Abdelghany | D6: 966549733284 - 966547160894 | E6: Alsaad - Vision | F6: faisal.skeik@alsaad.com.sa | G6: Tender | H6: Jeddah | I6: Send to Client | J6: 9619000 | K6: المشروع ده بقى Shortlisted على شركة السعد و شركة حسن علام ( و الي ماسك الباكدج بتاعتنا هو Vision ) و كمان شركة بس لسة مش عارف اسمها و حاليا احنا مستنيين نشوف هيرسى على مين و يبعتولنا Phase 2 ---- الشركات هي فريسينيه و حسن علام و السعد و ACC و اخر تقديم ليهم يوم الاحد | L6: 46132 | M6: No Updates | O6: =IFERROR(VALUE(SUBSTITUTE(TRIM(SUBSTITUTE(Projects_Follow_UP[[#This Row],[Est. value]],"SAR","")),",","")),0) -> 9619000 | R6: {=_xlfn.LET(_xlpm.x,_xlfn.XLOOKUP(A6,Dashboard!$M$61:$M$72,Dashboard!$J$61:$J$72,""),IF(_xlpm.x<>"",_xlpm.x,M6))} -> No Updates | S6: {=_xlfn.LET(_xlpm.x,_xlfn.XLOOKUP(A6,Dashboard!$M$61:$M$72,Dashboard!$K$61:$K$72,""),_xlpm.orig,N6,IF(_xlpm.x<>"",_xlpm.x,IF(OR(_xlpm.orig="",_xlpm.orig=0),"",_xlpm.orig)))} -> 46223
A7: PR1008 | B7: Alsalama Hospital | C7: Yasser Bahussin | D7: 966506694282 | E7: Alsalama Hospital | F7: yasser.bahussain@alsalamahospital.com | G7: In Hand | H7: Jeddah | I7: Send to Client | J7: 33000 | K7: عنده سيستم PA ببراند Honeywell Pava x618 و محتاج في ال announcement يكون بشكل معين بعت الحاجة لتيم التكنيكال و مستني منهم الرد | L7: 46132 | M7: مديره رجع بس لسة بيظبط الدنيا معاه و حددت معاه ميتنج الاسبوع الجي عشان اقعد انا و هو نتكلم في الاسعار | O7: =IFERROR(VALUE(SUBSTITUTE(TRIM(SUBSTITUTE(Projects_Follow_UP[[#This Row],[Est. value]],"SAR","")),",","")),0) -> 33000 | R7: {=_xlfn.LET(_xlpm.x,_xlfn.XLOOKUP(A7,Dashboard!$M$61:$M$72,Dashboard!$J$61:$J$72,""),IF(_xlpm.x<>"",_xlpm.x,M7))} -> مديره رجع بس لسة بيظبط الدنيا معاه و حددت معاه ميتنج الاسبوع الجي عشان اقعد انا و هو نتكلم في الاسعار | S7: {=_xlfn.LET(_xlpm.x,_xlfn.XLOOKUP(A7,Dashboard!$M$61:$M$72,Dashboard!$K$61:$K$72,""),_xlpm.orig,N7,IF(_xlpm.x<>"",_xlpm.x,IF(OR(_xlpm.orig="",_xlpm.orig=0),"",_xlpm.orig)))}
A8: PR1014 | B8: Zedca منافذ حدودية | C8: Omar Alsaad | D8: =_xlfn.XLOOKUP(Projects_Follow_UP[[#This Row],[Client Name]],'Hot Leads'!A:A,'Hot Leads'!B:B,0,0) -> 966549733284 | E8: =_xlfn.XLOOKUP(Projects_Follow_UP[[#This Row],[Client Phone Number]],'Hot Leads'!B:B,'Hot Leads'!C:C,0,0) -> Alsaad Contracting | F8: =_xlfn.XLOOKUP(Projects_Follow_UP[[#This Row],[Client Name]],'Hot Leads'!A:A,'Hot Leads'!F:F, ,0) -> omar.abdullah@alsaad.com.sa | G8: In Hand | H8: RedSea | I8: Gather Info. | K8: مشروع هيبقى مع الشركة دي قريب جدا و هيمضوا العقد المشروع ده بقاله سنتين و نص و لسة هيبدأوا شغل فيه الايام الجاية دي بس رتمه بطيئ شوية | L8: 46144 | M8: كلمته و قالي مفيش اي ابديت جديد لسة مستنيه لما يقولي اخر الابديت و كلمته تاني انهاردة بس لسة مردش | N8: 46160 | O8: =IFERROR(VALUE(SUBSTITUTE(TRIM(SUBSTITUTE(Projects_Follow_UP[[#This Row],[Est. value]],"SAR","")),",","")),0) -> 0 | R8: {=_xlfn.LET(_xlpm.x,_xlfn.XLOOKUP(A8,Dashboard!$M$61:$M$72,Dashboard!$J$61:$J$72,""),IF(_xlpm.x<>"",_xlpm.x,M8))} -> كلمته و قالي مفيش اي ابديت جديد لسة مستنيه لما يقولي اخر الابديت و كلمته تاني انهاردة بس لسة مردش | S8: {=_xlfn.LET(_xlpm.x,_xlfn.XLOOKUP(A8,Dashboard!$M$61:$M$72,Dashboard!$K$61:$K$72,""),_xlpm.orig,N8,IF(_xlpm.x<>"",_xlpm.x,IF(OR(_xlpm.orig="",_xlpm.orig=0),"",_xlpm.orig)))} -> 46160
A9: PR1015 | B9: Bab Al Khair Hospital Q4 | C9: Youssef Adwi | D9: =_xlfn.XLOOKUP(Projects_Follow_UP[[#This Row],[Client Name]],'Hot Leads'!A:A,'Hot Leads'!B:B,0,0) -> 966554711520 | E9: =_xlfn.XLOOKUP(Projects_Follow_UP[[#This Row],[Client Phone Number]],'Hot Leads'!B:B,'Hot Leads'!C:C,0,0) -> IHCC | F9: =_xlfn.XLOOKUP(Projects_Follow_UP[[#This Row],[Client Name]],'Hot Leads'!A:A,'Hot Leads'!F:F, ,0) -> y.adwi@ihcc.sa | G9: In Hand | H9: Makkah | I9: Send to Client | J9: 450000 | K9: مشروع خيري و المشروع هيروح للشركة الاقل سعر في كل حاجة | L9: 46146 | M9: المشروع حصل عليه Hold من SGH عشان البدجت مش مناسبة و لسة بيعملوا Value Engineering | O9: =IFERROR(VALUE(SUBSTITUTE(TRIM(SUBSTITUTE(Projects_Follow_UP[[#This Row],[Est. value]],"SAR","")),",","")),0) -> 450000 | R9: {=_xlfn.LET(_xlpm.x,_xlfn.XLOOKUP(A9,Dashboard!$M$61:$M$72,Dashboard!$J$61:$J$72,""),IF(_xlpm.x<>"",_xlpm.x,M9))} -> المشروع حصل عليه Hold من SGH عشان البدجت مش مناسبة و لسة بيعملوا Value Engineering | S9: {=_xlfn.LET(_xlpm.x,_xlfn.XLOOKUP(A9,Dashboard!$M$61:$M$72,Dashboard!$K$61:$K$72,""),_xlpm.orig,N9,IF(_xlpm.x<>"",_xlpm.x,IF(OR(_xlpm.orig="",_xlpm.orig=0),"",_xlpm.orig)))}
A10: PR1016 | B10: Mini Market in KAUST Q4 | C10: Omar El Hanoun | D10: =_xlfn.XLOOKUP(Projects_Follow_UP[[#This Row],[Client Name]],'Hot Leads'!A:A,'Hot Leads'!B:B,0,0) -> 966531895117 | E10: =_xlfn.XLOOKUP(Projects_Follow_UP[[#This Row],[Client Phone Number]],'Hot Leads'!B:B,'Hot Leads'!C:C,0,0) -> MACC | F10: =_xlfn.XLOOKUP(Projects_Follow_UP[[#This Row],[Client Name]],'Hot Leads'!A:A,'Hot Leads'!F:F, ,0) -> omer.elhanoun@macc-fm.com | G10: In Hand | H10: Jeddah | I10: Send to Client | J10: 95000 | K10: مشروع مهم MACC و محتاجين فيه FA و يكون فيه امكانيه انه يتربط على ال KAUST في المستقبل | L10: 46147 | M10: اتصلت بيه اكتر من مره و لسة مردش | O10: =IFERROR(VALUE(SUBSTITUTE(TRIM(SUBSTITUTE(Projects_Follow_UP[[#This Row],[Est. value]],"SAR","")),",","")),0) -> 95000 | R10: {=_xlfn.LET(_xlpm.x,_xlfn.XLOOKUP(A10,Dashboard!$M$61:$M$72,Dashboard!$J$61:$J$72,""),IF(_xlpm.x<>"",_xlpm.x,M10))} -> اتصلت بيه اكتر من مره و لسة مردش | S10: {=_xlfn.LET(_xlpm.x,_xlfn.XLOOKUP(A10,Dashboard!$M$61:$M$72,Dashboard!$K$61:$K$72,""),_xlpm.orig,N10,IF(_xlpm.x<>"",_xlpm.x,IF(OR(_xlpm.orig="",_xlpm.orig=0),"",_xlpm.orig)))} -> 46223
A11: PR1017 | B11: Al-Mukhmal Resort | C11: Omar Alsaad | D11: =_xlfn.XLOOKUP(Projects_Follow_UP[[#This Row],[Client Name]],'Hot Leads'!A:A,'Hot Leads'!B:B,0,0) -> 966549733284 | E11: =_xlfn.XLOOKUP(Projects_Follow_UP[[#This Row],[Client Phone Number]],'Hot Leads'!B:B,'Hot Leads'!C:C,0,0) -> Alsaad Contracting | F11: =_xlfn.XLOOKUP(Projects_Follow_UP[[#This Row],[Client Name]],'Hot Leads'!A:A,'Hot Leads'!F:F, ,0) -> omar.abdullah@alsaad.com.sa | G11: Tender | H11: Jeddah | I11: Hold | K11: مستني المشروعات التانيه تخلص عشان نخش في المشروع بس لما يرد عليا الاول اصلا | L11: 46147 | M11: لسة مفيش جديد عامله هول عشان عمر نفسه مش بيرد عليا لسة اول ما يرد كمل تسعير فالمشروع بلص ان مفيش تشانيل اصلا | N11: 46156 | O11: =IFERROR(VALUE(SUBSTITUTE(TRIM(SUBSTITUTE(Projects_Follow_UP[[#This Row],[Est. value]],"SAR","")),",","")),0) -> 0 | R11: {=_xlfn.LET(_xlpm.x,_xlfn.XLOOKUP(A11,Dashboard!$M$61:$M$72,Dashboard!$J$61:$J$72,""),IF(_xlpm.x<>"",_xlpm.x,M11))} -> لسة مفيش جديد عامله هول عشان عمر نفسه مش بيرد عليا لسة اول ما يرد كمل تسعير فالمشروع بلص ان مفيش تشانيل اصلا | S11: {=_xlfn.LET(_xlpm.x,_xlfn.XLOOKUP(A11,Dashboard!$M$61:$M$72,Dashboard!$K$61:$K$72,""),_xlpm.orig,N11,IF(_xlpm.x<>"",_xlpm.x,IF(OR(_xlpm.orig="",_xlpm.orig=0),"",_xlpm.orig)))} -> 46156
A12: PR1018 | B12: Rosemond Hotel | C12: Khaled Hussain | D12: =_xlfn.XLOOKUP(Projects_Follow_UP[[#This Row],[Client Name]],'Hot Leads'!A:A,'Hot Leads'!B:B,0,0) -> 966537929837 | E12: =_xlfn.XLOOKUP(Projects_Follow_UP[[#This Row],[Client Phone Number]],'Hot Leads'!B:B,'Hot Leads'!C:C,0,0) -> Creet | F12: =_xlfn.XLOOKUP(Projects_Follow_UP[[#This Row],[Client Name]],'Hot Leads'!A:A,'Hot Leads'!F:F, ,0) -> 0 | G12: In Hand | H12: Jeddah | I12: Lost | J12: 2490000 | K12: المشروع ده من خالد نفسه الي شغال جوه شركة كريت و عاوز يخلصه من بره بره و نطلعله عمولته المشروع ده مش مع Creet ده مع خالد نفسه بس | L12: 46148 | M12: المشروع هيخلص اقصى حاجة يوم السبت و المشروع ده مهم جدا لابعد حد عشان نقدر ناخد الباكدج كاملة | N12: 46151 | O12: =IFERROR(VALUE(SUBSTITUTE(TRIM(SUBSTITUTE(Projects_Follow_UP[[#This Row],[Est. value]],"SAR","")),",","")),0) -> 2490000 | R12: {=_xlfn.LET(_xlpm.x,_xlfn.XLOOKUP(A12,Dashboard!$M$61:$M$72,Dashboard!$J$61:$J$72,""),IF(_xlpm.x<>"",_xlpm.x,M12))} -> المشروع هيخلص اقصى حاجة يوم السبت و المشروع ده مهم جدا لابعد حد عشان نقدر ناخد الباكدج كاملة | S12: {=_xlfn.LET(_xlpm.x,_xlfn.XLOOKUP(A12,Dashboard!$M$61:$M$72,Dashboard!$K$61:$K$72,""),_xlpm.orig,N12,IF(_xlpm.x<>"",_xlpm.x,IF(OR(_xlpm.orig="",_xlpm.orig=0),"",_xlpm.orig)))} -> 46389
A13: PR1021 | B13: GRC Villas | C13: Ehab GRC | D13: =_xlfn.XLOOKUP(Projects_Follow_UP[[#This Row],[Client Name]],'Hot Leads'!A:A,'Hot Leads'!B:B,0,0) -> 966582792050 | E13: =_xlfn.XLOOKUP(Projects_Follow_UP[[#This Row],[Client Phone Number]],'Hot Leads'!B:B,'Hot Leads'!C:C,0,0) -> GRC | F13: =_xlfn.XLOOKUP(Projects_Follow_UP[[#This Row],[Client Name]],'Hot Leads'!A:A,'Hot Leads'!F:F, ,0) -> 0 | G13: In Hand | H13: Riyadh | I13: Send to Client | J13: 206000 | K13: المشروع اتقسم بيني و بين عبدالرحمن و الكوتيشن طلعت و بعتناها للراجل | L13: 46148 | M13: قالي انه عامل للمشاريع هولد و مستني يفضى عشان يقارن الاسعار الي بعتنهاله | O13: =IFERROR(VALUE(SUBSTITUTE(TRIM(SUBSTITUTE(Projects_Follow_UP[[#This Row],[Est. value]],"SAR","")),",","")),0) -> 206000 | R13: {=_xlfn.LET(_xlpm.x,_xlfn.XLOOKUP(A13,Dashboard!$M$61:$M$72,Dashboard!$J$61:$J$72,""),IF(_xlpm.x<>"",_xlpm.x,M13))} -> قالي انه عامل للمشاريع هولد و مستني يفضى عشان يقارن الاسعار الي بعتنهاله | S13: {=_xlfn.LET(_xlpm.x,_xlfn.XLOOKUP(A13,Dashboard!$M$61:$M$72,Dashboard!$K$61:$K$72,""),_xlpm.orig,N13,IF(_xlpm.x<>"",_xlpm.x,IF(OR(_xlpm.orig="",_xlpm.orig=0),"",_xlpm.orig)))} -> 46231
A14: PR1022 | B14: Qiddya Project | C14: Ehab GRC | D14: =_xlfn.XLOOKUP(Projects_Follow_UP[[#This Row],[Client Name]],'Hot Leads'!A:A,'Hot Leads'!B:B,0,0) -> 966582792050 | E14: =_xlfn.XLOOKUP(Projects_Follow_UP[[#This Row],[Client Phone Number]],'Hot Leads'!B:B,'Hot Leads'!C:C,0,0) -> GRC | F14: =_xlfn.XLOOKUP(Projects_Follow_UP[[#This Row],[Client Name]],'Hot Leads'!A:A,'Hot Leads'!F:F, ,0) -> 0 | G14: In Hand | H14: Riyadh | I14: Send to Client | J14: 220000 | K14: المشروع مع نفس الراجل مكتبه في جدة و مكان المشروع في الرياض و شغالين عليه انا و عبدالرحمن | L14: 46148 | M14: قالي انه عامل للمشاريع هولد و مستني يفضى عشان يقارن الاسعار الي بعتنهاله | O14: =IFERROR(VALUE(SUBSTITUTE(TRIM(SUBSTITUTE(Projects_Follow_UP[[#This Row],[Est. value]],"SAR","")),",","")),0) -> 220000 | R14: {=_xlfn.LET(_xlpm.x,_xlfn.XLOOKUP(A14,Dashboard!$M$61:$M$72,Dashboard!$J$61:$J$72,""),IF(_xlpm.x<>"",_xlpm.x,M14))} -> قالي انه عامل للمشاريع هولد و مستني يفضى عشان يقارن الاسعار الي بعتنهاله | S14: {=_xlfn.LET(_xlpm.x,_xlfn.XLOOKUP(A14,Dashboard!$M$61:$M$72,Dashboard!$K$61:$K$72,""),_xlpm.orig,N14,IF(_xlpm.x<>"",_xlpm.x,IF(OR(_xlpm.orig="",_xlpm.orig=0),"",_xlpm.orig)))} -> 46231
A15: PR1023 | B15: Sukoon Care Hospital | C15: Ayman Aburub | D15: =_xlfn.XLOOKUP(Projects_Follow_UP[[#This Row],[Client Name]],'Hot Leads'!A:A,'Hot Leads'!B:B,0,0) -> 966581469699 | E15: =_xlfn.XLOOKUP(Projects_Follow_UP[[#This Row],[Client Phone Number]],'Hot Leads'!B:B,'Hot Leads'!C:C,0,0) -> KFOCO | F15: =_xlfn.XLOOKUP(Projects_Follow_UP[[#This Row],[Client Name]],'Hot Leads'!A:A,'Hot Leads'!F:F, ,0) -> ak@kfoco.com | G15: In Hand | H15: Jeddah | I15: Gather Info. | K15: المشروع لسة الداتا بتاعته مع مهندس عبدالرحمن القفاص لسة مستنيه يبعتهالي و المشروع ده مع صاحب المهندس عبدرالحمن و هيبعتلي التفاصيل و كده هو مش مع ايمن الي انت كاتبه | L15: 46153 | M15: اتواصل مع ايمن شوف المشاريع الجديدة الي معاه | N15: 46158 | O15: =IFERROR(VALUE(SUBSTITUTE(TRIM(SUBSTITUTE(Projects_Follow_UP[[#This Row],[Est. value]],"SAR","")),",","")),0) -> 0 | R15: {=_xlfn.LET(_xlpm.x,_xlfn.XLOOKUP(A15,Dashboard!$M$61:$M$72,Dashboard!$J$61:$J$72,""),IF(_xlpm.x<>"",_xlpm.x,M15))} -> اتواصل مع ايمن شوف المشاريع الجديدة الي معاه | S15: {=_xlfn.LET(_xlpm.x,_xlfn.XLOOKUP(A15,Dashboard!$M$61:$M$72,Dashboard!$K$61:$K$72,""),_xlpm.orig,N15,IF(_xlpm.x<>"",_xlpm.x,IF(OR(_xlpm.orig="",_xlpm.orig=0),"",_xlpm.orig)))} -> 46158
A16: PR1025 | B16: MARAFY ALAROUS Roshan Group | C16: Helmy Abdelrazeq | D16: =_xlfn.XLOOKUP(Projects_Follow_UP[[#This Row],[Client Name]],'Hot Leads'!A:A,'Hot Leads'!B:B,0,0) -> 966560374964 | E16: =_xlfn.XLOOKUP(Projects_Follow_UP[[#This Row],[Client Phone Number]],'Hot Leads'!B:B,'Hot Leads'!C:C,0,0) -> AlShamela | F16: =_xlfn.XLOOKUP(Projects_Follow_UP[[#This Row],[Client Name]],'Hot Leads'!A:A,'Hot Leads'!F:F, ,0) -> hemlyac@alshamela.com.sa | G16: Tender | H16: Jeddah | I16: Send to Client | J16: 27765033 | K16: بعتنا الكوتيشن يوم 12/8 | L16: 46223 | M16: هتابع مع العميل | N16: 46250 | O16: =IFERROR(VALUE(SUBSTITUTE(TRIM(SUBSTITUTE(Projects_Follow_UP[[#This Row],[Est. value]],"SAR","")),",","")),0) -> 27765033 | R16: {=_xlfn.LET(_xlpm.x,_xlfn.XLOOKUP(A16,Dashboard!$M$61:$M$72,Dashboard!$J$61:$J$72,""),IF(_xlpm.x<>"",_xlpm.x,M16))} -> QT | S16: {=_xlfn.LET(_xlpm.x,_xlfn.XLOOKUP(A16,Dashboard!$M$61:$M$72,Dashboard!$K$61:$K$72,""),_xlpm.orig,N16,IF(_xlpm.x<>"",_xlpm.x,IF(OR(_xlpm.orig="",_xlpm.orig=0),"",_xlpm.orig)))} -> 46231
A17: PR1027 | B17: مبنى الهيئة العامة | C17: Abdelaziz Hassan | D17: =_xlfn.XLOOKUP(Projects_Follow_UP[[#This Row],[Client Name]],'Hot Leads'!A:A,'Hot Leads'!B:B,0,0) -> 966592851015 | E17: =_xlfn.XLOOKUP(Projects_Follow_UP[[#This Row],[Client Phone Number]],'Hot Leads'!B:B,'Hot Leads'!C:C,0,0) -> MAG المجال العربي | F17: =_xlfn.XLOOKUP(Projects_Follow_UP[[#This Row],[Client Name]],'Hot Leads'!A:A,'Hot Leads'!F:F, ,0) -> a.alessa@mag-sa.com | G17: In Hand | H17: Makkah | I17: Send to Client | J17: 47000 | K17: بعتهاله و بحاول اظبط معاه ميتنج بس هو مشغول جدا هروحله اول الاسبوع الجي | L17: 46223 | M17: QT | N17: 46228 | O17: =IFERROR(VALUE(SUBSTITUTE(TRIM(SUBSTITUTE(Projects_Follow_UP[[#This Row],[Est. value]],"SAR","")),",","")),0) -> 47000 | R17: {=_xlfn.LET(_xlpm.x,_xlfn.XLOOKUP(A17,Dashboard!$M$61:$M$72,Dashboard!$J$61:$J$72,""),IF(_xlpm.x<>"",_xlpm.x,M17))} -> QT | S17: {=_xlfn.LET(_xlpm.x,_xlfn.XLOOKUP(A17,Dashboard!$M$61:$M$72,Dashboard!$K$61:$K$72,""),_xlpm.orig,N17,IF(_xlpm.x<>"",_xlpm.x,IF(OR(_xlpm.orig="",_xlpm.orig=0),"",_xlpm.orig)))} -> 46228
A18: PR1029 | B18: BOULEVARD RESIDENTIAL | C18: Youssef Adwi | D18: =_xlfn.XLOOKUP(Projects_Follow_UP[[#This Row],[Client Name]],'Hot Leads'!A:A,'Hot Leads'!B:B,0,0) -> 966554711520 | E18: =_xlfn.XLOOKUP(Projects_Follow_UP[[#This Row],[Client Phone Number]],'Hot Leads'!B:B,'Hot Leads'!C:C,0,0) -> IHCC | F18: =_xlfn.XLOOKUP(Projects_Follow_UP[[#This Row],[Client Name]],'Hot Leads'!A:A,'Hot Leads'!F:F, ,0) -> y.adwi@ihcc.sa | G18: Tender | H18: Riyadh | I18: RFQ Processing | J18: 1209293 | K18: مستني رده لسة المشروع تندر | L18: 46226 | M18: مستني باقي الكوتيشن | N18: 46257 | O18: =IFERROR(VALUE(SUBSTITUTE(TRIM(SUBSTITUTE(Projects_Follow_UP[[#This Row],[Est. value]],"SAR","")),",","")),0) -> 1209293 | R18: {=_xlfn.LET(_xlpm.x,_xlfn.XLOOKUP(A18,Dashboard!$M$61:$M$72,Dashboard!$J$61:$J$72,""),IF(_xlpm.x<>"",_xlpm.x,M18))} -> QT | S18: {=_xlfn.LET(_xlpm.x,_xlfn.XLOOKUP(A18,Dashboard!$M$61:$M$72,Dashboard!$K$61:$K$72,""),_xlpm.orig,N18,IF(_xlpm.x<>"",_xlpm.x,IF(OR(_xlpm.orig="",_xlpm.orig=0),"",_xlpm.orig)))} -> 46235
A19: PR1030 | B19: مشروع تيسر | C19: Mohamed Abdelatif | D19: =_xlfn.XLOOKUP(Projects_Follow_UP[[#This Row],[Client Name]],'Hot Leads'!A:A,'Hot Leads'!B:B,0,0) -> 966545150782 | E19: =_xlfn.XLOOKUP(Projects_Follow_UP[[#This Row],[Client Phone Number]],'Hot Leads'!B:B,'Hot Leads'!C:C,0,0) -> تيسر للتجارة | F19: =_xlfn.XLOOKUP(Projects_Follow_UP[[#This Row],[Client Name]],'Hot Leads'!A:A,'Hot Leads'!F:F, ,0) -> 0 | G19: In Hand | H19: Makkah | I19: Send to Client | J19: 5400000 | K19: هنغير الباكدج بتاعت المشروع و لسة مستنيها | L19: 46231 | M19: QT | N19: 46257 | O19: =IFERROR(VALUE(SUBSTITUTE(TRIM(SUBSTITUTE(Projects_Follow_UP[[#This Row],[Est. value]],"SAR","")),",","")),0) -> 5400000 | R19: {=_xlfn.LET(_xlpm.x,_xlfn.XLOOKUP(A19,Dashboard!$M$61:$M$72,Dashboard!$J$61:$J$72,""),IF(_xlpm.x<>"",_xlpm.x,M19))} -> QT | S19: {=_xlfn.LET(_xlpm.x,_xlfn.XLOOKUP(A19,Dashboard!$M$61:$M$72,Dashboard!$K$61:$K$72,""),_xlpm.orig,N19,IF(_xlpm.x<>"",_xlpm.x,IF(OR(_xlpm.orig="",_xlpm.orig=0),"",_xlpm.orig)))} -> 46229
A20: PR1031 | B20: Bn Dawood Al-Hamrah | C20: Mohamed | D20: =_xlfn.XLOOKUP(Projects_Follow_UP[[#This Row],[Client Name]],'Hot Leads'!A:A,'Hot Leads'!B:B,0,0) -> 966500810545 | E20: =_xlfn.XLOOKUP(Projects_Follow_UP[[#This Row],[Client Phone Number]],'Hot Leads'!B:B,'Hot Leads'!C:C,0,0) -> سعود الصاعدي | F20: =_xlfn.XLOOKUP(Projects_Follow_UP[[#This Row],[Client Name]],'Hot Leads'!A:A,'Hot Leads'!F:F, ,0) -> 0 | G20: In Hand | H20: Makkah | I20: RFQ Processing | K20: لسة شغالين عليه | L20: 46236 | M20: QT | N20: 46243 | O20: =IFERROR(VALUE(SUBSTITUTE(TRIM(SUBSTITUTE(Projects_Follow_UP[[#This Row],[Est. value]],"SAR","")),",","")),0) -> 0 | R20: {=_xlfn.LET(_xlpm.x,_xlfn.XLOOKUP(A20,Dashboard!$M$61:$M$72,Dashboard!$J$61:$J$72,""),IF(_xlpm.x<>"",_xlpm.x,M20))} -> QT | S20: {=_xlfn.LET(_xlpm.x,_xlfn.XLOOKUP(A20,Dashboard!$M$61:$M$72,Dashboard!$K$61:$K$72,""),_xlpm.orig,N20,IF(_xlpm.x<>"",_xlpm.x,IF(OR(_xlpm.orig="",_xlpm.orig=0),"",_xlpm.orig)))} -> 46243
A21: PR1034 | B21: MIRAF ONE | C21: Othman Mohamed | D21: =_xlfn.XLOOKUP(Projects_Follow_UP[[#This Row],[Client Name]],'Hot Leads'!A:A,'Hot Leads'!B:B,0,0) -> 966537964254 | E21: =_xlfn.XLOOKUP(Projects_Follow_UP[[#This Row],[Client Phone Number]],'Hot Leads'!B:B,'Hot Leads'!C:C,0,0) -> EMCO TECH Buna Sister Company | F21: =_xlfn.XLOOKUP(Projects_Follow_UP[[#This Row],[Client Name]],'Hot Leads'!A:A,'Hot Leads'!F:F, ,0) -> 0 | G21: In Hand | H21: Khobar | I21: Send to Client | J21: 8836100 | K21: اتكلمت مع امه لا اله الا الله و مفيش حد فيهم بيدي اي معلومة | L21: 46243 | M21: كلمت مهندس محمد عشان اتابع معاه | N21: 46267 | O21: =IFERROR(VALUE(SUBSTITUTE(TRIM(SUBSTITUTE(Projects_Follow_UP[[#This Row],[Est. value]],"SAR","")),",","")),0) -> 8836100 | R21: {=_xlfn.LET(_xlpm.x,_xlfn.XLOOKUP(A21,Dashboard!$M$61:$M$72,Dashboard!$J$61:$J$72,""),IF(_xlpm.x<>"",_xlpm.x,M21))} -> كلمت مهندس محمد عشان اتابع معاه | S21: {=_xlfn.LET(_xlpm.x,_xlfn.XLOOKUP(A21,Dashboard!$M$61:$M$72,Dashboard!$K$61:$K$72,""),_xlpm.orig,N21,IF(_xlpm.x<>"",_xlpm.x,IF(OR(_xlpm.orig="",_xlpm.orig=0),"",_xlpm.orig)))} -> 46267
A22: PR1036 | B22: Marriot Jeddah | D22: =_xlfn.XLOOKUP(Projects_Follow_UP[[#This Row],[Client Name]],'Hot Leads'!A:A,'Hot Leads'!B:B,0,0) -> 0 | E22: =_xlfn.XLOOKUP(Projects_Follow_UP[[#This Row],[Client Phone Number]],'Hot Leads'!B:B,'Hot Leads'!C:C,0,0) -> 0 | F22: =_xlfn.XLOOKUP(Projects_Follow_UP[[#This Row],[Client Name]],'Hot Leads'!A:A,'Hot Leads'!F:F, ,0) -> 0 | O22: =IFERROR(VALUE(SUBSTITUTE(TRIM(SUBSTITUTE(Projects_Follow_UP[[#This Row],[Est. value]],"SAR","")),",","")),0) -> 0 | R22: {=_xlfn.LET(_xlpm.x,_xlfn.XLOOKUP(A22,Dashboard!$M$61:$M$72,Dashboard!$J$61:$J$72,""),IF(_xlpm.x<>"",_xlpm.x,M22))} -> 0 | S22: {=_xlfn.LET(_xlpm.x,_xlfn.XLOOKUP(A22,Dashboard!$M$61:$M$72,Dashboard!$K$61:$K$72,""),_xlpm.orig,N22,IF(_xlpm.x<>"",_xlpm.x,IF(OR(_xlpm.orig="",_xlpm.orig=0),"",_xlpm.orig)))}
A23: PR1037 | B23: RUA Al Madinah Superblock 5 | C23: Mazen Vision | D23: =_xlfn.XLOOKUP(Projects_Follow_UP[[#This Row],[Client Name]],'Hot Leads'!A:A,'Hot Leads'!B:B,0,0) -> 966547160894 | E23: =_xlfn.XLOOKUP(Projects_Follow_UP[[#This Row],[Client Phone Number]],'Hot Leads'!B:B,'Hot Leads'!C:C,0,0) -> Vision Contracting | F23: =_xlfn.XLOOKUP(Projects_Follow_UP[[#This Row],[Client Name]],'Hot Leads'!A:A,'Hot Leads'!F:F, ,0) -> m.hassan@vision-cc.com | G23: Tender | H23: Riyadh | I23: RFQ Processing | J23: 16000000 | K23: مخلصين بس ال BMS و ال Lighting Control ب 16 مليون والباقي ميار شغاله عليه لسة | O23: =IFERROR(VALUE(SUBSTITUTE(TRIM(SUBSTITUTE(Projects_Follow_UP[[#This Row],[Est. value]],"SAR","")),",","")),0) -> 16000000 | R23: {=_xlfn.LET(_xlpm.x,_xlfn.XLOOKUP(A23,Dashboard!$M$61:$M$72,Dashboard!$J$61:$J$72,""),IF(_xlpm.x<>"",_xlpm.x,M23))} -> 0 | S23: {=_xlfn.LET(_xlpm.x,_xlfn.XLOOKUP(A23,Dashboard!$M$61:$M$72,Dashboard!$K$61:$K$72,""),_xlpm.orig,N23,IF(_xlpm.x<>"",_xlpm.x,IF(OR(_xlpm.orig="",_xlpm.orig=0),"",_xlpm.orig)))}
A24: PR1038 | B24: Roya Al Haram | D24: =_xlfn.XLOOKUP(Projects_Follow_UP[[#This Row],[Client Name]],'Hot Leads'!A:A,'Hot Leads'!B:B,0,0) -> 0 | E24: =_xlfn.XLOOKUP(Projects_Follow_UP[[#This Row],[Client Phone Number]],'Hot Leads'!B:B,'Hot Leads'!C:C,0,0) -> 0 | F24: =_xlfn.XLOOKUP(Projects_Follow_UP[[#This Row],[Client Name]],'Hot Leads'!A:A,'Hot Leads'!F:F, ,0) -> 0 | G24: In Hand | H24: Makkah | I24: RFQ Processing | J24: 950000 | K24: ال Lighting Control خلص و ال BMS خلص -- Send | L24: 46260 | O24: =IFERROR(VALUE(SUBSTITUTE(TRIM(SUBSTITUTE(Projects_Follow_UP[[#This Row],[Est. value]],"SAR","")),",","")),0) -> 950000 | R24: {=_xlfn.LET(_xlpm.x,_xlfn.XLOOKUP(A24,Dashboard!$M$61:$M$72,Dashboard!$J$61:$J$72,""),IF(_xlpm.x<>"",_xlpm.x,M24))} -> 0 | S24: {=_xlfn.LET(_xlpm.x,_xlfn.XLOOKUP(A24,Dashboard!$M$61:$M$72,Dashboard!$K$61:$K$72,""),_xlpm.orig,N24,IF(_xlpm.x<>"",_xlpm.x,IF(OR(_xlpm.orig="",_xlpm.orig=0),"",_xlpm.orig)))}
A25: PR1039 | B25: Almoosa Schools | C25: Eslam Abo Elezz | D25: =_xlfn.XLOOKUP(Projects_Follow_UP[[#This Row],[Client Name]],'Hot Leads'!A:A,'Hot Leads'!B:B,0,0) -> 966595291415 | E25: =_xlfn.XLOOKUP(Projects_Follow_UP[[#This Row],[Client Phone Number]],'Hot Leads'!B:B,'Hot Leads'!C:C,0,0) -> Albadayeel البدائل | F25: =_xlfn.XLOOKUP(Projects_Follow_UP[[#This Row],[Client Name]],'Hot Leads'!A:A,'Hot Leads'!F:F, ,0) -> 0 | K25: حصل فيه كتير جدا جدا | O25: =IFERROR(VALUE(SUBSTITUTE(TRIM(SUBSTITUTE(Projects_Follow_UP[[#This Row],[Est. value]],"SAR","")),",","")),0) -> 0 | R25: {=_xlfn.LET(_xlpm.x,_xlfn.XLOOKUP(A25,Dashboard!$M$61:$M$72,Dashboard!$J$61:$J$72,""),IF(_xlpm.x<>"",_xlpm.x,M25))} -> 0 | S25: {=_xlfn.LET(_xlpm.x,_xlfn.XLOOKUP(A25,Dashboard!$M$61:$M$72,Dashboard!$K$61:$K$72,""),_xlpm.orig,N25,IF(_xlpm.x<>"",_xlpm.x,IF(OR(_xlpm.orig="",_xlpm.orig=0),"",_xlpm.orig)))}
A26: PR1040 | B26: رابطة العالم الاسلامي | C26: Omar Albatal | D26: =_xlfn.XLOOKUP(Projects_Follow_UP[[#This Row],[Client Name]],'Hot Leads'!A:A,'Hot Leads'!B:B,0,0) -> 966503355231 | E26: =_xlfn.XLOOKUP(Projects_Follow_UP[[#This Row],[Client Phone Number]],'Hot Leads'!B:B,'Hot Leads'!C:C,0,0) -> Al-Waref Contracting Comapny | F26: =_xlfn.XLOOKUP(Projects_Follow_UP[[#This Row],[Client Name]],'Hot Leads'!A:A,'Hot Leads'!F:F, ,0) -> 0 | G26: In Hand | H26: Makkah | I26: RFQ Processing | K26: شغالين على ال BMS و ال PA , CCTV , Passive , | O26: =IFERROR(VALUE(SUBSTITUTE(TRIM(SUBSTITUTE(Projects_Follow_UP[[#This Row],[Est. value]],"SAR","")),",","")),0) -> 0 | R26: {=_xlfn.LET(_xlpm.x,_xlfn.XLOOKUP(A26,Dashboard!$M$61:$M$72,Dashboard!$J$61:$J$72,""),IF(_xlpm.x<>"",_xlpm.x,M26))} -> 0 | S26: {=_xlfn.LET(_xlpm.x,_xlfn.XLOOKUP(A26,Dashboard!$M$61:$M$72,Dashboard!$K$61:$K$72,""),_xlpm.orig,N26,IF(_xlpm.x<>"",_xlpm.x,IF(OR(_xlpm.orig="",_xlpm.orig=0),"",_xlpm.orig)))}
A27: PR1041 | B27: WATCO Madina | D27: =_xlfn.XLOOKUP(Projects_Follow_UP[[#This Row],[Client Name]],'Hot Leads'!A:A,'Hot Leads'!B:B,0,0) -> 0 | E27: =_xlfn.XLOOKUP(Projects_Follow_UP[[#This Row],[Client Phone Number]],'Hot Leads'!B:B,'Hot Leads'!C:C,0,0) -> 0 | F27: =_xlfn.XLOOKUP(Projects_Follow_UP[[#This Row],[Client Name]],'Hot Leads'!A:A,'Hot Leads'!F:F, ,0) -> 0 | O27: =IFERROR(VALUE(SUBSTITUTE(TRIM(SUBSTITUTE(Projects_Follow_UP[[#This Row],[Est. value]],"SAR","")),",","")),0) -> 0 | R27: {=_xlfn.LET(_xlpm.x,_xlfn.XLOOKUP(A27,Dashboard!$M$61:$M$72,Dashboard!$J$61:$J$72,""),IF(_xlpm.x<>"",_xlpm.x,M27))} -> 0 | S27: {=_xlfn.LET(_xlpm.x,_xlfn.XLOOKUP(A27,Dashboard!$M$61:$M$72,Dashboard!$K$61:$K$72,""),_xlpm.orig,N27,IF(_xlpm.x<>"",_xlpm.x,IF(OR(_xlpm.orig="",_xlpm.orig=0),"",_xlpm.orig)))}
A28: PR1042 | B28: Caterion CLA | D28: =_xlfn.XLOOKUP(Projects_Follow_UP[[#This Row],[Client Name]],'Hot Leads'!A:A,'Hot Leads'!B:B,0,0) -> 0 | E28: =_xlfn.XLOOKUP(Projects_Follow_UP[[#This Row],[Client Phone Number]],'Hot Leads'!B:B,'Hot Leads'!C:C,0,0) -> 0 | F28: =_xlfn.XLOOKUP(Projects_Follow_UP[[#This Row],[Client Name]],'Hot Leads'!A:A,'Hot Leads'!F:F, ,0) -> 0 | O28: =IFERROR(VALUE(SUBSTITUTE(TRIM(SUBSTITUTE(Projects_Follow_UP[[#This Row],[Est. value]],"SAR","")),",","")),0) -> 0 | R28: {=_xlfn.LET(_xlpm.x,_xlfn.XLOOKUP(A28,Dashboard!$M$61:$M$72,Dashboard!$J$61:$J$72,""),IF(_xlpm.x<>"",_xlpm.x,M28))} -> 0 | S28: {=_xlfn.LET(_xlpm.x,_xlfn.XLOOKUP(A28,Dashboard!$M$61:$M$72,Dashboard!$K$61:$K$72,""),_xlpm.orig,N28,IF(_xlpm.x<>"",_xlpm.x,IF(OR(_xlpm.orig="",_xlpm.orig=0),"",_xlpm.orig)))}
A29: PR1043 | B29: Al- TAhliyah Business Park | C29: Salman MEP Manager | D29: =_xlfn.XLOOKUP(Projects_Follow_UP[[#This Row],[Client Name]],'Hot Leads'!A:A,'Hot Leads'!B:B,0,0) -> 966572572847 | E29: =_xlfn.XLOOKUP(Projects_Follow_UP[[#This Row],[Client Phone Number]],'Hot Leads'!B:B,'Hot Leads'!C:C,0,0) -> BAK United Arabia | F29: =_xlfn.XLOOKUP(Projects_Follow_UP[[#This Row],[Client Name]],'Hot Leads'!A:A,'Hot Leads'!F:F, ,0) -> salmanshah@bakunited.sa | G29: In Hand | H29: Jeddah | I29: Negotiation | J29: 220000 | K29: مستني ابعتله سعر كوتيشن بوش عشان هو لازم يكون معاه 2 اوبشن يوريهم للاستشاري اما فارديون بتاع هانويل | O29: =IFERROR(VALUE(SUBSTITUTE(TRIM(SUBSTITUTE(Projects_Follow_UP[[#This Row],[Est. value]],"SAR","")),",","")),0) -> 220000 | R29: {=_xlfn.LET(_xlpm.x,_xlfn.XLOOKUP(A29,Dashboard!$M$61:$M$72,Dashboard!$J$61:$J$72,""),IF(_xlpm.x<>"",_xlpm.x,M29))} -> 0 | S29: {=_xlfn.LET(_xlpm.x,_xlfn.XLOOKUP(A29,Dashboard!$M$61:$M$72,Dashboard!$K$61:$K$72,""),_xlpm.orig,N29,IF(_xlpm.x<>"",_xlpm.x,IF(OR(_xlpm.orig="",_xlpm.orig=0),"",_xlpm.orig)))}
A30: PR1044 | B30: Saudi German Hospital | D30: =_xlfn.XLOOKUP(Projects_Follow_UP[[#This Row],[Client Name]],'Hot Leads'!A:A,'Hot Leads'!B:B,0,0) -> 0 | E30: =_xlfn.XLOOKUP(Projects_Follow_UP[[#This Row],[Client Phone Number]],'Hot Leads'!B:B,'Hot Leads'!C:C,0,0) -> 0 | F30: =_xlfn.XLOOKUP(Projects_Follow_UP[[#This Row],[Client Name]],'Hot Leads'!A:A,'Hot Leads'!F:F, ,0) -> 0 | G30: In Hand | H30: Jeddah | O30: =IFERROR(VALUE(SUBSTITUTE(TRIM(SUBSTITUTE(Projects_Follow_UP[[#This Row],[Est. value]],"SAR","")),",","")),0) -> 0 | R30: {=_xlfn.LET(_xlpm.x,_xlfn.XLOOKUP(A30,Dashboard!$M$61:$M$72,Dashboard!$J$61:$J$72,""),IF(_xlpm.x<>"",_xlpm.x,M30))} -> 0 | S30: {=_xlfn.LET(_xlpm.x,_xlfn.XLOOKUP(A30,Dashboard!$M$61:$M$72,Dashboard!$K$61:$K$72,""),_xlpm.orig,N30,IF(_xlpm.x<>"",_xlpm.x,IF(OR(_xlpm.orig="",_xlpm.orig=0),"",_xlpm.orig)))}
A31: PR1045 | D31: =_xlfn.XLOOKUP(Projects_Follow_UP[[#This Row],[Client Name]],'Hot Leads'!A:A,'Hot Leads'!B:B,0,0) -> 0 | E31: =_xlfn.XLOOKUP(Projects_Follow_UP[[#This Row],[Client Phone Number]],'Hot Leads'!B:B,'Hot Leads'!C:C,0,0) -> 0 | F31: =_xlfn.XLOOKUP(Projects_Follow_UP[[#This Row],[Client Name]],'Hot Leads'!A:A,'Hot Leads'!F:F, ,0) -> 0 | O31: =IFERROR(VALUE(SUBSTITUTE(TRIM(SUBSTITUTE(Projects_Follow_UP[[#This Row],[Est. value]],"SAR","")),",","")),0) -> 0 | R31: {=_xlfn.LET(_xlpm.x,_xlfn.XLOOKUP(A31,Dashboard!$M$61:$M$72,Dashboard!$J$61:$J$72,""),IF(_xlpm.x<>"",_xlpm.x,M31))} -> 0 | S31: {=_xlfn.LET(_xlpm.x,_xlfn.XLOOKUP(A31,Dashboard!$M$61:$M$72,Dashboard!$K$61:$K$72,""),_xlpm.orig,N31,IF(_xlpm.x<>"",_xlpm.x,IF(OR(_xlpm.orig="",_xlpm.orig=0),"",_xlpm.orig)))}
A32: PR1046 | D32: =_xlfn.XLOOKUP(Projects_Follow_UP[[#This Row],[Client Name]],'Hot Leads'!A:A,'Hot Leads'!B:B,0,0) -> 0 | E32: =_xlfn.XLOOKUP(Projects_Follow_UP[[#This Row],[Client Phone Number]],'Hot Leads'!B:B,'Hot Leads'!C:C,0,0) -> 0 | F32: =_xlfn.XLOOKUP(Projects_Follow_UP[[#This Row],[Client Name]],'Hot Leads'!A:A,'Hot Leads'!F:F, ,0) -> 0 | O32: =IFERROR(VALUE(SUBSTITUTE(TRIM(SUBSTITUTE(Projects_Follow_UP[[#This Row],[Est. value]],"SAR","")),",","")),0) -> 0 | R32: {=_xlfn.LET(_xlpm.x,_xlfn.XLOOKUP(A32,Dashboard!$M$61:$M$72,Dashboard!$J$61:$J$72,""),IF(_xlpm.x<>"",_xlpm.x,M32))} -> 0 | S32: {=_xlfn.LET(_xlpm.x,_xlfn.XLOOKUP(A32,Dashboard!$M$61:$M$72,Dashboard!$K$61:$K$72,""),_xlpm.orig,N32,IF(_xlpm.x<>"",_xlpm.x,IF(OR(_xlpm.orig="",_xlpm.orig=0),"",_xlpm.orig)))}
A33: PR1047 | D33: =_xlfn.XLOOKUP(Projects_Follow_UP[[#This Row],[Client Name]],'Hot Leads'!A:A,'Hot Leads'!B:B,0,0) -> 0 | E33: =_xlfn.XLOOKUP(Projects_Follow_UP[[#This Row],[Client Phone Number]],'Hot Leads'!B:B,'Hot Leads'!C:C,0,0) -> 0 | F33: =_xlfn.XLOOKUP(Projects_Follow_UP[[#This Row],[Client Name]],'Hot Leads'!A:A,'Hot Leads'!F:F, ,0) -> 0 | O33: =IFERROR(VALUE(SUBSTITUTE(TRIM(SUBSTITUTE(Projects_Follow_UP[[#This Row],[Est. value]],"SAR","")),",","")),0) -> 0 | R33: {=_xlfn.LET(_xlpm.x,_xlfn.XLOOKUP(A33,Dashboard!$M$61:$M$72,Dashboard!$J$61:$J$72,""),IF(_xlpm.x<>"",_xlpm.x,M33))} -> 0 | S33: {=_xlfn.LET(_xlpm.x,_xlfn.XLOOKUP(A33,Dashboard!$M$61:$M$72,Dashboard!$K$61:$K$72,""),_xlpm.orig,N33,IF(_xlpm.x<>"",_xlpm.x,IF(OR(_xlpm.orig="",_xlpm.orig=0),"",_xlpm.orig)))}
A34: PR1048 | D34: =_xlfn.XLOOKUP(Projects_Follow_UP[[#This Row],[Client Name]],'Hot Leads'!A:A,'Hot Leads'!B:B,0,0) -> 0 | E34: =_xlfn.XLOOKUP(Projects_Follow_UP[[#This Row],[Client Phone Number]],'Hot Leads'!B:B,'Hot Leads'!C:C,0,0) -> 0 | F34: =_xlfn.XLOOKUP(Projects_Follow_UP[[#This Row],[Client Name]],'Hot Leads'!A:A,'Hot Leads'!F:F, ,0) -> 0 | O34: =IFERROR(VALUE(SUBSTITUTE(TRIM(SUBSTITUTE(Projects_Follow_UP[[#This Row],[Est. value]],"SAR","")),",","")),0) -> 0 | R34: {=_xlfn.LET(_xlpm.x,_xlfn.XLOOKUP(A34,Dashboard!$M$61:$M$72,Dashboard!$J$61:$J$72,""),IF(_xlpm.x<>"",_xlpm.x,M34))} -> 0 | S34: {=_xlfn.LET(_xlpm.x,_xlfn.XLOOKUP(A34,Dashboard!$M$61:$M$72,Dashboard!$K$61:$K$72,""),_xlpm.orig,N34,IF(_xlpm.x<>"",_xlpm.x,IF(OR(_xlpm.orig="",_xlpm.orig=0),"",_xlpm.orig)))}
A35: PR1049 | D35: =_xlfn.XLOOKUP(Projects_Follow_UP[[#This Row],[Client Name]],'Hot Leads'!A:A,'Hot Leads'!B:B,0,0) -> 0 | E35: =_xlfn.XLOOKUP(Projects_Follow_UP[[#This Row],[Client Phone Number]],'Hot Leads'!B:B,'Hot Leads'!C:C,0,0) -> 0 | F35: =_xlfn.XLOOKUP(Projects_Follow_UP[[#This Row],[Client Name]],'Hot Leads'!A:A,'Hot Leads'!F:F, ,0) -> 0 | O35: =IFERROR(VALUE(SUBSTITUTE(TRIM(SUBSTITUTE(Projects_Follow_UP[[#This Row],[Est. value]],"SAR","")),",","")),0) -> 0 | R35: {=_xlfn.LET(_xlpm.x,_xlfn.XLOOKUP(A35,Dashboard!$M$61:$M$72,Dashboard!$J$61:$J$72,""),IF(_xlpm.x<>"",_xlpm.x,M35))} -> 0 | S35: {=_xlfn.LET(_xlpm.x,_xlfn.XLOOKUP(A35,Dashboard!$M$61:$M$72,Dashboard!$K$61:$K$72,""),_xlpm.orig,N35,IF(_xlpm.x<>"",_xlpm.x,IF(OR(_xlpm.orig="",_xlpm.orig=0),"",_xlpm.orig)))}
A36: PR1050 | D36: =_xlfn.XLOOKUP(Projects_Follow_UP[[#This Row],[Client Name]],'Hot Leads'!A:A,'Hot Leads'!B:B,0,0) -> 0 | E36: =_xlfn.XLOOKUP(Projects_Follow_UP[[#This Row],[Client Phone Number]],'Hot Leads'!B:B,'Hot Leads'!C:C,0,0) -> 0 | F36: =_xlfn.XLOOKUP(Projects_Follow_UP[[#This Row],[Client Name]],'Hot Leads'!A:A,'Hot Leads'!F:F, ,0) -> 0 | O36: =IFERROR(VALUE(SUBSTITUTE(TRIM(SUBSTITUTE(Projects_Follow_UP[[#This Row],[Est. value]],"SAR","")),",","")),0) -> 0 | R36: {=_xlfn.LET(_xlpm.x,_xlfn.XLOOKUP(A36,Dashboard!$M$61:$M$72,Dashboard!$J$61:$J$72,""),IF(_xlpm.x<>"",_xlpm.x,M36))} -> 0 | S36: {=_xlfn.LET(_xlpm.x,_xlfn.XLOOKUP(A36,Dashboard!$M$61:$M$72,Dashboard!$K$61:$K$72,""),_xlpm.orig,N36,IF(_xlpm.x<>"",_xlpm.x,IF(OR(_xlpm.orig="",_xlpm.orig=0),"",_xlpm.orig)))}
A37: PR1051 | D37: =_xlfn.XLOOKUP(Projects_Follow_UP[[#This Row],[Client Name]],'Hot Leads'!A:A,'Hot Leads'!B:B,0,0) -> 0 | E37: =_xlfn.XLOOKUP(Projects_Follow_UP[[#This Row],[Client Phone Number]],'Hot Leads'!B:B,'Hot Leads'!C:C,0,0) -> 0 | F37: =_xlfn.XLOOKUP(Projects_Follow_UP[[#This Row],[Client Name]],'Hot Leads'!A:A,'Hot Leads'!F:F, ,0) -> 0 | O37: =IFERROR(VALUE(SUBSTITUTE(TRIM(SUBSTITUTE(Projects_Follow_UP[[#This Row],[Est. value]],"SAR","")),",","")),0) -> 0 | R37: {=_xlfn.LET(_xlpm.x,_xlfn.XLOOKUP(A37,Dashboard!$M$61:$M$72,Dashboard!$J$61:$J$72,""),IF(_xlpm.x<>"",_xlpm.x,M37))} -> 0 | S37: {=_xlfn.LET(_xlpm.x,_xlfn.XLOOKUP(A37,Dashboard!$M$61:$M$72,Dashboard!$K$61:$K$72,""),_xlpm.orig,N37,IF(_xlpm.x<>"",_xlpm.x,IF(OR(_xlpm.orig="",_xlpm.orig=0),"",_xlpm.orig)))}
A38: PR1052 | D38: =_xlfn.XLOOKUP(Projects_Follow_UP[[#This Row],[Client Name]],'Hot Leads'!A:A,'Hot Leads'!B:B,0,0) -> 0 | E38: =_xlfn.XLOOKUP(Projects_Follow_UP[[#This Row],[Client Phone Number]],'Hot Leads'!B:B,'Hot Leads'!C:C,0,0) -> 0 | F38: =_xlfn.XLOOKUP(Projects_Follow_UP[[#This Row],[Client Name]],'Hot Leads'!A:A,'Hot Leads'!F:F, ,0) -> 0 | O38: =IFERROR(VALUE(SUBSTITUTE(TRIM(SUBSTITUTE(Projects_Follow_UP[[#This Row],[Est. value]],"SAR","")),",","")),0) -> 0 | R38: {=_xlfn.LET(_xlpm.x,_xlfn.XLOOKUP(A38,Dashboard!$M$61:$M$72,Dashboard!$J$61:$J$72,""),IF(_xlpm.x<>"",_xlpm.x,M38))} -> 0 | S38: {=_xlfn.LET(_xlpm.x,_xlfn.XLOOKUP(A38,Dashboard!$M$61:$M$72,Dashboard!$K$61:$K$72,""),_xlpm.orig,N38,IF(_xlpm.x<>"",_xlpm.x,IF(OR(_xlpm.orig="",_xlpm.orig=0),"",_xlpm.orig)))}
A39: PR1053 | D39: =_xlfn.XLOOKUP(Projects_Follow_UP[[#This Row],[Client Name]],'Hot Leads'!A:A,'Hot Leads'!B:B,0,0) -> 0 | E39: =_xlfn.XLOOKUP(Projects_Follow_UP[[#This Row],[Client Phone Number]],'Hot Leads'!B:B,'Hot Leads'!C:C,0,0) -> 0 | F39: =_xlfn.XLOOKUP(Projects_Follow_UP[[#This Row],[Client Name]],'Hot Leads'!A:A,'Hot Leads'!F:F, ,0) -> 0 | O39: =IFERROR(VALUE(SUBSTITUTE(TRIM(SUBSTITUTE(Projects_Follow_UP[[#This Row],[Est. value]],"SAR","")),",","")),0) -> 0 | R39: {=_xlfn.LET(_xlpm.x,_xlfn.XLOOKUP(A39,Dashboard!$M$61:$M$72,Dashboard!$J$61:$J$72,""),IF(_xlpm.x<>"",_xlpm.x,M39))} -> 0 | S39: {=_xlfn.LET(_xlpm.x,_xlfn.XLOOKUP(A39,Dashboard!$M$61:$M$72,Dashboard!$K$61:$K$72,""),_xlpm.orig,N39,IF(_xlpm.x<>"",_xlpm.x,IF(OR(_xlpm.orig="",_xlpm.orig=0),"",_xlpm.orig)))}
A40: PR1054 | D40: =_xlfn.XLOOKUP(Projects_Follow_UP[[#This Row],[Client Name]],'Hot Leads'!A:A,'Hot Leads'!B:B,0,0) -> 0 | E40: =_xlfn.XLOOKUP(Projects_Follow_UP[[#This Row],[Client Phone Number]],'Hot Leads'!B:B,'Hot Leads'!C:C,0,0) -> 0 | F40: =_xlfn.XLOOKUP(Projects_Follow_UP[[#This Row],[Client Name]],'Hot Leads'!A:A,'Hot Leads'!F:F, ,0) -> 0 | O40: =IFERROR(VALUE(SUBSTITUTE(TRIM(SUBSTITUTE(Projects_Follow_UP[[#This Row],[Est. value]],"SAR","")),",","")),0) -> 0 | R40: {=_xlfn.LET(_xlpm.x,_xlfn.XLOOKUP(A40,Dashboard!$M$61:$M$72,Dashboard!$J$61:$J$72,""),IF(_xlpm.x<>"",_xlpm.x,M40))} -> 0 | S40: {=_xlfn.LET(_xlpm.x,_xlfn.XLOOKUP(A40,Dashboard!$M$61:$M$72,Dashboard!$K$61:$K$72,""),_xlpm.orig,N40,IF(_xlpm.x<>"",_xlpm.x,IF(OR(_xlpm.orig="",_xlpm.orig=0),"",_xlpm.orig)))}
...

Sheet Hot Leads
A1: Name | B1: Phone | C1: Company | D1: Google Map Location | E1: Company Based on | F1: Email | G1: Position | H1: Last Call Date | I1: Notes | J1: Next Follow Up Notes | K1: Next Follow Up Date | L1: Gone To Referral ? | M1: Current Action Required | N1: Current Action Date
A2: Mohamed Hussain | B2: 966562846152 | C2: Creet | D2: https://maps.app.goo.gl/dDuLptLbo71wA8du9 | E2: Jeddah | F2: m.hussain@creet.net | G2: Procurement Engineer | H2: 46131 | I2: بعتلنا مشروع New Industrial Factory عشان نعدل الكميات و نبعتله السعر الجديد و لسة | J2: اول ما الكوتيشن تخلص هكلمه | M2: {=_xlfn.LET(_xlpm.x,_xlfn.XLOOKUP(Hot_Leads[[#This Row],[Phone]],Dashboard!$M$44:$M$58,Dashboard!$J$44:$J$58,""),IF(_xlpm.x<>"",_xlpm.x,Hot_Leads[[#This Row],[Next Follow Up Notes]]))} -> اول ما الكوتيشن تخلص هكلمه | N2: {=_xlfn.LET(_xlpm.x,_xlfn.XLOOKUP(Hot_Leads[[#This Row],[Phone]],Dashboard!$M$44:$M$58,Dashboard!$K$44:$K$58,""),_xlpm.orig,Hot_Leads[[#This Row],[Next Follow Up Date]],IF(_xlpm.x<>"",_xlpm.x,IF(OR(_xlpm.orig="",_xlpm.orig=0),"",_xlpm.orig)))}
A3: Nasser Bn Mounir | B3: 966540374734 | C3: Inshaa Aljezra | D3: https://maps.app.goo.gl/JzJ3RJ7bUkrwNRUZA | E3: Makkah | F3: -- | G3: Procurement Manager | H3: 46176 | I3: خلصوا المشاريع الي معاهم حاليا و فيه مشروع تاني معاهم بعد الحج قالي ابعتلي البروفايل و ابعتلي البزنس كارد | J3: لسة على نفس المشروع القديم و مفيش جديد خالص | M3: {=_xlfn.LET(_xlpm.x,_xlfn.XLOOKUP(Hot_Leads[[#This Row],[Phone]],Dashboard!$M$44:$M$58,Dashboard!$J$44:$J$58,""),IF(_xlpm.x<>"",_xlpm.x,Hot_Leads[[#This Row],[Next Follow Up Notes]]))} -> لسة على نفس المشروع القديم و مفيش جديد خالص | N3: {=_xlfn.LET(_xlpm.x,_xlfn.XLOOKUP(Hot_Leads[[#This Row],[Phone]],Dashboard!$M$44:$M$58,Dashboard!$K$44:$K$58,""),_xlpm.orig,Hot_Leads[[#This Row],[Next Follow Up Date]],IF(_xlpm.x<>"",_xlpm.x,IF(OR(_xlpm.orig="",_xlpm.orig=0),"",_xlpm.orig)))}
A4: Asghar Ali | B4: 966552196041 | C4: ALghanem | F4: asgar.ali@orc-constructions.com | G4: Engineering rep | H4: 46131 | I4: معنهمش مشاريع جديدة | J4: Send Business Card & Company Profile | M4: {=_xlfn.LET(_xlpm.x,_xlfn.XLOOKUP(Hot_Leads[[#This Row],[Phone]],Dashboard!$M$44:$M$58,Dashboard!$J$44:$J$58,""),IF(_xlpm.x<>"",_xlpm.x,Hot_Leads[[#This Row],[Next Follow Up Notes]]))} -> Send Business Card & Company Profile | N4: {=_xlfn.LET(_xlpm.x,_xlfn.XLOOKUP(Hot_Leads[[#This Row],[Phone]],Dashboard!$M$44:$M$58,Dashboard!$K$44:$K$58,""),_xlpm.orig,Hot_Leads[[#This Row],[Next Follow Up Date]],IF(_xlpm.x<>"",_xlpm.x,IF(OR(_xlpm.orig="",_xlpm.orig=0),"",_xlpm.orig)))}
A5: Mark Brian | B5: 966550796895 | C5: Hexagon | D5: https://maps.app.goo.gl/iSnFecR4DVJ6biXV9 | E5: Dammam | F5: Brian.Nemi@hexagon.sa | G5: Technical Manager | H5: 46131 | I5: Na | J5: Na | M5: {=_xlfn.LET(_xlpm.x,_xlfn.XLOOKUP(Hot_Leads[[#This Row],[Phone]],Dashboard!$M$44:$M$58,Dashboard!$J$44:$J$58,""),IF(_xlpm.x<>"",_xlpm.x,Hot_Leads[[#This Row],[Next Follow Up Notes]]))} -> Na | N5: {=_xlfn.LET(_xlpm.x,_xlfn.XLOOKUP(Hot_Leads[[#This Row],[Phone]],Dashboard!$M$44:$M$58,Dashboard!$K$44:$K$58,""),_xlpm.orig,Hot_Leads[[#This Row],[Next Follow Up Date]],IF(_xlpm.x<>"",_xlpm.x,IF(OR(_xlpm.orig="",_xlpm.orig=0),"",_xlpm.orig)))}
A6: Mohamed Abdelhady | B6: 966547017064 | C6: GAC | D6: https://maps.app.goo.gl/a1oNGzQ8BDT2fyjHA | E6: Dammam | F6: mohammed.abdulhadi@gac-cont.com | G6: Engineering Manager | H6: 46131 | I6: معاه مشروع Digital Signage Screen في مستشفى الملك فهد التخصصي في الدمام و تفاصيل المشروع معاك في النوت و مستني منك كوتيشن | J6: Send Quotation and Ask for the sister company for BMS | L6: Abdelrahman | M6: {=_xlfn.LET(_xlpm.x,_xlfn.XLOOKUP(Hot_Leads[[#This Row],[Phone]],Dashboard!$M$44:$M$58,Dashboard!$J$44:$J$58,""),IF(_xlpm.x<>"",_xlpm.x,Hot_Leads[[#This Row],[Next Follow Up Notes]]))} -> Send Quotation and Ask for the sister company for BMS | N6: {=_xlfn.LET(_xlpm.x,_xlfn.XLOOKUP(Hot_Leads[[#This Row],[Phone]],Dashboard!$M$44:$M$58,Dashboard!$K$44:$K$58,""),_xlpm.orig,Hot_Leads[[#This Row],[Next Follow Up Date]],IF(_xlpm.x<>"",_xlpm.x,IF(OR(_xlpm.orig="",_xlpm.orig=0),"",_xlpm.orig)))}
A7: Ibrahim Ahmed | B7: 966546468592 | C7: Al-Fanar | D7: https://maps.app.goo.gl/c5pWiicmKMLBYKo58 | E7: Riyadh | G7: Engineering Manager | H7: 46176 | I7: ساب شركة السعد و راح شركة الفنار و معاه مشروع King Salman Park ده تندر لسة و مفيش جديد خالص حمدي جلال هو الي بيتابع معاه | J7: هكلمه يوم الاتنين عشان اعرف التفاصيل الجديدة | M7: {=_xlfn.LET(_xlpm.x,_xlfn.XLOOKUP(Hot_Leads[[#This Row],[Phone]],Dashboard!$M$44:$M$58,Dashboard!$J$44:$J$58,""),IF(_xlpm.x<>"",_xlpm.x,Hot_Leads[[#This Row],[Next Follow Up Notes]]))} -> هكلمه يوم الاتنين عشان اعرف التفاصيل الجديدة | N7: {=_xlfn.LET(_xlpm.x,_xlfn.XLOOKUP(Hot_Leads[[#This Row],[Phone]],Dashboard!$M$44:$M$58,Dashboard!$K$44:$K$58,""),_xlpm.orig,Hot_Leads[[#This Row],[Next Follow Up Date]],IF(_xlpm.x<>"",_xlpm.x,IF(OR(_xlpm.orig="",_xlpm.orig=0),"",_xlpm.orig)))} -> 46146
A8: Yasser Bahussin | B8: 966506694282 | C8: Alsalama Hospital | D8: https://maps.app.goo.gl/hduVAmcVWzY67pd2A | E8: Jeddah | F8: yasser.bahussain@alsalamahospital.com | G8: Engineering manager | H8: 46131 | I8: ابعتله البروفايل و اتابع معاه كل اسبوع لحد ما يفتكرني دايما | J8: عندي ميتنج معاه يوم الاحد | M8: {=_xlfn.LET(_xlpm.x,_xlfn.XLOOKUP(Hot_Leads[[#This Row],[Phone]],Dashboard!$M$44:$M$58,Dashboard!$J$44:$J$58,""),IF(_xlpm.x<>"",_xlpm.x,Hot_Leads[[#This Row],[Next Follow Up Notes]]))} -> قالي ان البرنامج هيرسى علينا و مستني بس موفقه الادارة | N8: {=_xlfn.LET(_xlpm.x,_xlfn.XLOOKUP(Hot_Leads[[#This Row],[Phone]],Dashboard!$M$44:$M$58,Dashboard!$K$44:$K$58,""),_xlpm.orig,Hot_Leads[[#This Row],[Next Follow Up Date]],IF(_xlpm.x<>"",_xlpm.x,IF(OR(_xlpm.orig="",_xlpm.orig=0),"",_xlpm.orig)))} -> 46250
A9: Ibrahim Abdelhamid | B9: 966500029803 | C9: Redcon International | D9: -- | E9: Riyadh | F9: ibrahim.abdelhamid@redconinternational.com | G9: Engineering manager | H9: 46132 | I9: عاوز يسعر Spine Mall و ال Sports Club بتاع مشروع Benan TMG طلعت مصطفى و حولت الكونتاكت لمهندس حمدي عشان المكتب بتاعهم في الرياض | J9: ده خلاص بقا مع مهندس حمدي | L9: Hamdy | M9: {=_xlfn.LET(_xlpm.x,_xlfn.XLOOKUP(Hot_Leads[[#This Row],[Phone]],Dashboard!$M$44:$M$58,Dashboard!$J$44:$J$58,""),IF(_xlpm.x<>"",_xlpm.x,Hot_Leads[[#This Row],[Next Follow Up Notes]]))} -> ده خلاص بقا مع مهندس حمدي | N9: {=_xlfn.LET(_xlpm.x,_xlfn.XLOOKUP(Hot_Leads[[#This Row],[Phone]],Dashboard!$M$44:$M$58,Dashboard!$K$44:$K$58,""),_xlpm.orig,Hot_Leads[[#This Row],[Next Follow Up Date]],IF(_xlpm.x<>"",_xlpm.x,IF(OR(_xlpm.orig="",_xlpm.orig=0),"",_xlpm.orig)))}
A10: Hussni | B10: 966532001107 | C10: Jash | F10: hussni@jash.com.sa | G10: - | H10: 46132 | I10: عنده مشروع تجديد صالة الامير فيصل للفنون فيها Barriers , CCTV , BMS و قالي ان انا سالت عليكم و انتم سعركم غالي جدا | J10: اداني رقم مهندس تاني هكلمه دلوقتي عشان نروح نعمل معاينه | M10: {=_xlfn.LET(_xlpm.x,_xlfn.XLOOKUP(Hot_Leads[[#This Row],[Phone]],Dashboard!$M$44:$M$58,Dashboard!$J$44:$J$58,""),IF(_xlpm.x<>"",_xlpm.x,Hot_Leads[[#This Row],[Next Follow Up Notes]]))} -> اداني رقم مهندس تاني هكلمه دلوقتي عشان نروح نعمل معاينه | N10: {=_xlfn.LET(_xlpm.x,_xlfn.XLOOKUP(Hot_Leads[[#This Row],[Phone]],Dashboard!$M$44:$M$58,Dashboard!$K$44:$K$58,""),_xlpm.orig,Hot_Leads[[#This Row],[Next Follow Up Date]],IF(_xlpm.x<>"",_xlpm.x,IF(OR(_xlpm.orig="",_xlpm.orig=0),"",_xlpm.orig)))}
A11: Mohamed Elkholy | B11: 966541016847 | C11: Fairmont Makkah | E11: Makkah | G11: Engineering manager | H11: 46132 | I11: ده مهم عنده سيستم عاوز ينفذه في الفندق و قالي ابعتلي الميل بتاعك عشان ابعتلك تسعرلي | J11: كلمته و قالي الحاجة وصلتني و انه كان مشغول و هيبعت المشروع على الميل على طول | M11: {=_xlfn.LET(_xlpm.x,_xlfn.XLOOKUP(Hot_Leads[[#This Row],[Phone]],Dashboard!$M$44:$M$58,Dashboard!$J$44:$J$58,""),IF(_xlpm.x<>"",_xlpm.x,Hot_Leads[[#This Row],[Next Follow Up Notes]]))} -> مفيش اخبار جديدة عنه | N11: {=_xlfn.LET(_xlpm.x,_xlfn.XLOOKUP(Hot_Leads[[#This Row],[Phone]],Dashboard!$M$44:$M$58,Dashboard!$K$44:$K$58,""),_xlpm.orig,Hot_Leads[[#This Row],[Next Follow Up Date]],IF(_xlpm.x<>"",_xlpm.x,IF(OR(_xlpm.orig="",_xlpm.orig=0),"",_xlpm.orig)))} -> 46243
A12: Refaat | B12: 201118383863 | C12: SIAC KSA Branch | G12: Project Manager | H12: 46132 | I12: كان معاهم مشروعين و هم خلاص في مرحلة التسليم الاخيرة و مفيش معاهم حاجة تاني حاليا | J12: Follow up Next Week | M12: {=_xlfn.LET(_xlpm.x,_xlfn.XLOOKUP(Hot_Leads[[#This Row],[Phone]],Dashboard!$M$44:$M$58,Dashboard!$J$44:$J$58,""),IF(_xlpm.x<>"",_xlpm.x,Hot_Leads[[#This Row],[Next Follow Up Notes]]))} -> Follow up Next Week | N12: {=_xlfn.LET(_xlpm.x,_xlfn.XLOOKUP(Hot_Leads[[#This Row],[Phone]],Dashboard!$M$44:$M$58,Dashboard!$K$44:$K$58,""),_xlpm.orig,Hot_Leads[[#This Row],[Next Follow Up Date]],IF(_xlpm.x<>"",_xlpm.x,IF(OR(_xlpm.orig="",_xlpm.orig=0),"",_xlpm.orig)))}
A13: Helmy Abdelrazeq | B13: 966560374964 | C13: AlShamela | E13: Jeddah | F13: hemlyac@alshamela.com.sa | G13: Project Manager | H13: 46133 | I13: عاوز فايل ال Pre Qualification بتاعنا على الميل عشان يعرف احنا ممكن نشتغل معاهم في ايه | J13: تابع معاه يوم الاحد | M13: {=_xlfn.LET(_xlpm.x,_xlfn.XLOOKUP(Hot_Leads[[#This Row],[Phone]],Dashboard!$M$44:$M$58,Dashboard!$J$44:$J$58,""),IF(_xlpm.x<>"",_xlpm.x,Hot_Leads[[#This Row],[Next Follow Up Notes]]))} -> تابع معاه يوم الاحد | N13: {=_xlfn.LET(_xlpm.x,_xlfn.XLOOKUP(Hot_Leads[[#This Row],[Phone]],Dashboard!$M$44:$M$58,Dashboard!$K$44:$K$58,""),_xlpm.orig,Hot_Leads[[#This Row],[Next Follow Up Date]],IF(_xlpm.x<>"",_xlpm.x,IF(OR(_xlpm.orig="",_xlpm.orig=0),"",_xlpm.orig)))}
A14: شركة رؤى الحرم المكي | H14: 46133 | I14: عاوز حد من هناك ضروري اعرف المشاريع الي عندهم | M14: {=_xlfn.LET(_xlpm.x,_xlfn.XLOOKUP(Hot_Leads[[#This Row],[Phone]],Dashboard!$M$44:$M$58,Dashboard!$J$44:$J$58,""),IF(_xlpm.x<>"",_xlpm.x,Hot_Leads[[#This Row],[Next Follow Up Notes]]))} -> 0 | N14: {=_xlfn.LET(_xlpm.x,_xlfn.XLOOKUP(Hot_Leads[[#This Row],[Phone]],Dashboard!$M$44:$M$58,Dashboard!$K$44:$K$58,""),_xlpm.orig,Hot_Leads[[#This Row],[Next Follow Up Date]],IF(_xlpm.x<>"",_xlpm.x,IF(OR(_xlpm.orig="",_xlpm.orig=0),"",_xlpm.orig)))}
A15: Mohamed Taqash | B15: 966569972444 | C15: Al-Saif | E15: Jeddah | G15: Project Manager | H15: 46176 | I15: ده مهندس عماد كان مقدمله مشروع IMC كنت بتابع معاه بس مفيش معلومات جديدة و قالي انه هيدي رقمي للمشتريات عشان يبعتولي لو فيه مشاريع جديدة | J15: Follow Up Next Week | M15: {=_xlfn.LET(_xlpm.x,_xlfn.XLOOKUP(Hot_Leads[[#This Row],[Phone]],Dashboard!$M$44:$M$58,Dashboard!$J$44:$J$58,""),IF(_xlpm.x<>"",_xlpm.x,Hot_Leads[[#This Row],[Next Follow Up Notes]]))} -> Follow Up Next Week | N15: {=_xlfn.LET(_xlpm.x,_xlfn.XLOOKUP(Hot_Leads[[#This Row],[Phone]],Dashboard!$M$44:$M$58,Dashboard!$K$44:$K$58,""),_xlpm.orig,Hot_Leads[[#This Row],[Next Follow Up Date]],IF(_xlpm.x<>"",_xlpm.x,IF(OR(_xlpm.orig="",_xlpm.orig=0),"",_xlpm.orig)))} -> 46140
C16: Freyssinet Saudi Arabia | D16: https://maps.app.goo.gl/h5ByLCjX7i9xPuA27 | E16: Jeddah | H16: 46134 | I16: الشركة دي من ال shortlisted الي المفروض نبعتلها في مشروع IMC كمان و اخر تقديم ليهم هو يوم الاحد 26-4-2026 | J16: Book a Visit | M16: {=_xlfn.LET(_xlpm.x,_xlfn.XLOOKUP(Hot_Leads[[#This Row],[Phone]],Dashboard!$M$44:$M$58,Dashboard!$J$44:$J$58,""),IF(_xlpm.x<>"",_xlpm.x,Hot_Leads[[#This Row],[Next Follow Up Notes]]))} -> Book a Visit | N16: {=_xlfn.LET(_xlpm.x,_xlfn.XLOOKUP(Hot_Leads[[#This Row],[Phone]],Dashboard!$M$44:$M$58,Dashboard!$K$44:$K$58,""),_xlpm.orig,Hot_Leads[[#This Row],[Next Follow Up Date]],IF(_xlpm.x<>"",_xlpm.x,IF(OR(_xlpm.orig="",_xlpm.orig=0),"",_xlpm.orig)))}
